[2023-12-25T21:12:02.147+0000] {taskinstance.py:1165} INFO - Dependencies all met for <TaskInstance: target_dag.process_ml manual__2023-12-24T00:00:00+00:00 [queued]>
[2023-12-25T21:12:02.154+0000] {taskinstance.py:1165} INFO - Dependencies all met for <TaskInstance: target_dag.process_ml manual__2023-12-24T00:00:00+00:00 [queued]>
[2023-12-25T21:12:02.154+0000] {taskinstance.py:1362} INFO - 
--------------------------------------------------------------------------------
[2023-12-25T21:12:02.154+0000] {taskinstance.py:1363} INFO - Starting attempt 1 of 1
[2023-12-25T21:12:02.154+0000] {taskinstance.py:1364} INFO - 
--------------------------------------------------------------------------------
[2023-12-25T21:12:02.170+0000] {taskinstance.py:1383} INFO - Executing <Task(BashOperator): process_ml> on 2023-12-24 00:00:00+00:00
[2023-12-25T21:12:02.177+0000] {standard_task_runner.py:55} INFO - Started process 382 to run task
[2023-12-25T21:12:02.179+0000] {standard_task_runner.py:82} INFO - Running: ['***', 'tasks', 'run', 'target_dag', 'process_ml', 'manual__2023-12-24T00:00:00+00:00', '--job-id', '156', '--raw', '--subdir', 'DAGS_FOLDER/target_dag.py', '--cfg-path', '/tmp/tmptoxco5no']
[2023-12-25T21:12:02.180+0000] {standard_task_runner.py:83} INFO - Job 156: Subtask process_ml
[2023-12-25T21:12:02.234+0000] {task_command.py:376} INFO - Running <TaskInstance: target_dag.process_ml manual__2023-12-24T00:00:00+00:00 [running]> on host d2fc15a9183d
[2023-12-25T21:12:02.278+0000] {abstractoperator.py:421} ERROR - Exception rendering Jinja template for task 'process_ml', field 'bash_command'. Template: "echo '{{ dag_run.conf['path]}}'"
Traceback (most recent call last):
  File "/home/airflow/.local/lib/python3.7/site-packages/airflow/models/abstractoperator.py", line 414, in _do_render_template_fields
    seen_oids,
  File "/home/airflow/.local/lib/python3.7/site-packages/airflow/models/abstractoperator.py", line 470, in render_template
    template = jinja_env.from_string(value)
  File "/home/airflow/.local/lib/python3.7/site-packages/jinja2/environment.py", line 1105, in from_string
    return cls.from_code(self, self.compile(source), gs, None)
  File "/home/airflow/.local/lib/python3.7/site-packages/jinja2/environment.py", line 768, in compile
    self.handle_exception(source=source_hint)
  File "/home/airflow/.local/lib/python3.7/site-packages/jinja2/environment.py", line 936, in handle_exception
    raise rewrite_traceback_stack(source=source)
  File "<unknown>", line 1, in template
jinja2.exceptions.TemplateSyntaxError: unexpected end of template, expected ','.
[2023-12-25T21:12:02.295+0000] {taskinstance.py:1851} ERROR - Task failed with exception
Traceback (most recent call last):
  File "/home/airflow/.local/lib/python3.7/site-packages/airflow/models/taskinstance.py", line 1457, in _run_raw_task
    self._execute_task_with_callbacks(context, test_mode)
  File "/home/airflow/.local/lib/python3.7/site-packages/airflow/models/taskinstance.py", line 1576, in _execute_task_with_callbacks
    task_orig = self.render_templates(context=context)
  File "/home/airflow/.local/lib/python3.7/site-packages/airflow/models/taskinstance.py", line 2199, in render_templates
    original_task.render_template_fields(context)
  File "/home/airflow/.local/lib/python3.7/site-packages/airflow/models/baseoperator.py", line 1193, in render_template_fields
    self._do_render_template_fields(self, self.template_fields, context, jinja_env, set())
  File "/home/airflow/.local/lib/python3.7/site-packages/airflow/utils/session.py", line 75, in wrapper
    return func(*args, session=session, **kwargs)
  File "/home/airflow/.local/lib/python3.7/site-packages/airflow/models/abstractoperator.py", line 414, in _do_render_template_fields
    seen_oids,
  File "/home/airflow/.local/lib/python3.7/site-packages/airflow/models/abstractoperator.py", line 470, in render_template
    template = jinja_env.from_string(value)
  File "/home/airflow/.local/lib/python3.7/site-packages/jinja2/environment.py", line 1105, in from_string
    return cls.from_code(self, self.compile(source), gs, None)
  File "/home/airflow/.local/lib/python3.7/site-packages/jinja2/environment.py", line 768, in compile
    self.handle_exception(source=source_hint)
  File "/home/airflow/.local/lib/python3.7/site-packages/jinja2/environment.py", line 936, in handle_exception
    raise rewrite_traceback_stack(source=source)
  File "<unknown>", line 1, in template
jinja2.exceptions.TemplateSyntaxError: unexpected end of template, expected ','.
[2023-12-25T21:12:02.320+0000] {taskinstance.py:1406} INFO - Marking task as FAILED. dag_id=target_dag, task_id=process_ml, execution_date=20231224T000000, start_date=20231225T211202, end_date=20231225T211202
[2023-12-25T21:12:02.336+0000] {standard_task_runner.py:105} ERROR - Failed to execute job 156 for task process_ml (unexpected end of template, expected ','.; 382)
[2023-12-25T21:12:02.351+0000] {local_task_job.py:164} INFO - Task exited with return code 1
[2023-12-25T21:12:02.371+0000] {local_task_job.py:273} INFO - 0 downstream tasks scheduled from follow-on schedule check
